2019-01-14T08:21:39.3415413-05:00 0HLJQ4CRC2G55:00000001 [INF] Request starting HTTP/1.1 GET http://localhost:5000/api/values   (ca22a1cb)
2019-01-14T08:21:40.3085441-05:00 0HLJQ4CRC2G55:00000001 [INF] Executing action method "InvoiceManagerWeb.Controllers.ValuesController.Get (InvoiceManagerWeb)" with arguments (null) - ModelState is Valid (ba7f4ac2)
2019-01-14T08:21:40.3113118-05:00 0HLJQ4CRC2G55:00000001 [INF] This is test message (4feb13e4)
2019-01-14T08:21:55.8684903-05:00 0HLJQ4CRC2G55:00000001 [INF] Executed action "InvoiceManagerWeb.Controllers.ValuesController.Get (InvoiceManagerWeb)" in 15550.6449ms (afa2e885)
2019-01-14T08:21:56.0726673-05:00 0HLJQ4CRC2G55:00000001 [ERR] An unhandled exception has occurred: Could not find a part of the path 'E:\Kunden\homepages\30\d767043508\www\apilog\MyLogFile.txt'. (777bd7e9)
System.IO.DirectoryNotFoundException: Could not find a part of the path 'E:\Kunden\homepages\30\d767043508\www\apilog\MyLogFile.txt'.
   at System.IO.FileStream.OpenHandle(FileMode mode, FileShare share, FileOptions options)
   at System.IO.FileStream..ctor(String path, FileMode mode, FileAccess access, FileShare share, Int32 bufferSize, FileOptions options)
   at System.IO.StreamWriter..ctor(String path, Boolean append, Encoding encoding, Int32 bufferSize)
   at System.IO.StreamWriter..ctor(String path, Boolean append)
   at System.IO.File.CreateText(String path)
   at InvoiceManagerWeb.Controllers.ValuesController.writeToFile(String message) in C:\Users\Viraj\source\repos\InvoiceManager\InvoiceManagerWeb\Controllers\ValuesController.cs:line 40
   at InvoiceManagerWeb.Controllers.ValuesController.Get() in C:\Users\Viraj\source\repos\InvoiceManager\InvoiceManagerWeb\Controllers\ValuesController.cs:line 32
   at lambda_method(Closure , Object , Object[] )
   at Microsoft.Extensions.Internal.ObjectMethodExecutor.Execute(Object target, Object[] parameters)
   at Microsoft.AspNetCore.Mvc.Internal.ControllerActionInvoker.<InvokeActionMethodAsync>d__12.MoveNext()
--- End of stack trace from previous location where exception was thrown ---
   at System.Runtime.ExceptionServices.ExceptionDispatchInfo.Throw()
   at System.Runtime.CompilerServices.TaskAwaiter.HandleNonSuccessAndDebuggerNotification(Task task)
   at Microsoft.AspNetCore.Mvc.Internal.ControllerActionInvoker.<InvokeNextActionFilterAsync>d__10.MoveNext()
--- End of stack trace from previous location where exception was thrown ---
   at System.Runtime.ExceptionServices.ExceptionDispatchInfo.Throw()
   at Microsoft.AspNetCore.Mvc.Internal.ControllerActionInvoker.Rethrow(ActionExecutedContext context)
   at Microsoft.AspNetCore.Mvc.Internal.ControllerActionInvoker.Next(State& next, Scope& scope, Object& state, Boolean& isCompleted)
   at Microsoft.AspNetCore.Mvc.Internal.ControllerActionInvoker.<InvokeInnerFilterAsync>d__14.MoveNext()
--- End of stack trace from previous location where exception was thrown ---
   at System.Runtime.ExceptionServices.ExceptionDispatchInfo.Throw()
   at System.Runtime.CompilerServices.TaskAwaiter.HandleNonSuccessAndDebuggerNotification(Task task)
   at Microsoft.AspNetCore.Mvc.Internal.ResourceInvoker.<InvokeNextResourceFilter>d__22.MoveNext()
--- End of stack trace from previous location where exception was thrown ---
   at System.Runtime.ExceptionServices.ExceptionDispatchInfo.Throw()
   at Microsoft.AspNetCore.Mvc.Internal.ResourceInvoker.Rethrow(ResourceExecutedContext context)
   at Microsoft.AspNetCore.Mvc.Internal.ResourceInvoker.Next(State& next, Scope& scope, Object& state, Boolean& isCompleted)
   at Microsoft.AspNetCore.Mvc.Internal.ResourceInvoker.<InvokeFilterPipelineAsync>d__17.MoveNext()
--- End of stack trace from previous location where exception was thrown ---
   at System.Runtime.ExceptionServices.ExceptionDispatchInfo.Throw()
   at System.Runtime.CompilerServices.TaskAwaiter.HandleNonSuccessAndDebuggerNotification(Task task)
   at Microsoft.AspNetCore.Mvc.Internal.ResourceInvoker.<InvokeAsync>d__15.MoveNext()
--- End of stack trace from previous location where exception was thrown ---
   at System.Runtime.ExceptionServices.ExceptionDispatchInfo.Throw()
   at System.Runtime.CompilerServices.TaskAwaiter.HandleNonSuccessAndDebuggerNotification(Task task)
   at Microsoft.AspNetCore.Builder.RouterMiddleware.<Invoke>d__4.MoveNext()
--- End of stack trace from previous location where exception was thrown ---
   at System.Runtime.ExceptionServices.ExceptionDispatchInfo.Throw()
   at System.Runtime.CompilerServices.TaskAwaiter.HandleNonSuccessAndDebuggerNotification(Task task)
   at Microsoft.AspNetCore.Diagnostics.ExceptionHandlerMiddleware.<Invoke>d__6.MoveNext()
2019-01-14T08:21:56.1239181-05:00 0HLJQ4CRC2G55:00000001 [INF] Request finished in 17505.9342ms 500  (791a596a)
2019-01-14T08:21:56.6091267-05:00 0HLJQ4CRC2G55:00000002 [INF] Request starting HTTP/1.1 GET http://localhost:5000/favicon.ico   (ca22a1cb)
2019-01-14T08:21:56.6135353-05:00 0HLJQ4CRC2G55:00000002 [INF] Request finished in 4.2157ms 404  (791a596a)
